Workbook

Sheet simulador_lista
A1: SIMULADOR COM LISTA DE SELEÇÃO | AA1: display | AB1: codigo | AC1: fase | AD1: grupo | AE1: cobranca | AF1: preco | AG1: unidade | AH1: item | AI1: natureza | AJ1: eh_prato_principal
AA2: MD-002 | Coqueteis de Frutas, suave para ir criando o clima de festa | R$ 4,40 | AB2: MD-002 | AC2: Antes do Sim | AD2: personalizacao | AE2: por pessoa | AF2: 4.4 | AG2: pessoa | AH2: Coqueteis de Frutas, suave para ir criando o clima de festa | AI2: Adicional real
A3: Campo | B3: Valor | C3: Observação | D3: Regras automáticas | E3: Valor | F3: Observação | AA3: MD-004 | Bruschetta tradicional, Caponata italiana, Dadinho de tapioca, Croquete de carne, Espetinho caprese, Escondidinho de Carne/Calabresa | R$ 14,00 | AB3: MD-004 | AC3: Depois do Sim | AD3: entradas | AE3: por pessoa | AF3: 14 | AG3: pessoa | AH3: Bruschetta tradicional, Caponata italiana, Dadinho de tapioca, Croquete de carne, Espetinho caprese, Escondidinho de Carne/Calabresa | AI3: Adicional real
A4: Convidados | B4: 100 | C4: Digite a quantidade de convidados. | D4: Data do casamento | E4: 46556 | F4: Digite a data real do casamento. | AA4: MD-005 | Bolinho de bacalhau, Bruschetta de cogumelos, Canapés finos, Queijo Brie, Tábua de frios, Cuscus marroquino, Barquinha de salpicão, Escondidinho de Carne/Calabresa | R$ 25,00 | AB4: MD-005 | AC4: Depois do Sim | AD4: entradas | AE4: por pessoa | AF4: 25 | AG4: pessoa | AH4: Bolinho de bacalhau, Bruschetta de cogumelos, Canapés finos, Queijo Brie, Tábua de frios, Cuscus marroquino, Barquinha de salpicão, Escondidinho de Carne/Calabresa | AI4: Adicional real
A5: Regra de período | B5: REG-006 | C5: Escolha apenas o período/horário. A data do casamento ajusta automaticamente o dia comercial via aba feriados. | D5: Multiplicador por data | E5: =IF($E$4="",1,MAX(1,SUMIFS(regras_reajuste_data!$G$2:$G$49,regras_reajuste_data!$C$2:$C$49,"<="&$E$4,regras_reajuste_data!$D$2:$D$49,">="&$E$4,regras_reajuste_data!$B$2:$B$49,"ativo"))) -> 1.24 | F5: Busca na aba regras_reajuste_data. | AA5: MD-007 | Alcatra ao molho de manga | R$ 55,00 | AB5: MD-007 | AC5: Sabores Principais | AD5: prato_principal | AE5: por pessoa | AF5: 55 | AG5: pessoa | AH5: Alcatra ao molho de manga | AI5: Adicional real
A6: Exclusividade do dia? | B6: NÃO | C6: SIM adiciona o valor de exclusividade da regra escolhida. | D6: Acréscimo fixo por data | E6: =IF($E$4="",0,SUMIFS(regras_reajuste_data!$H$2:$H$49,regras_reajuste_data!$C$2:$C$49,"<="&$E$4,regras_reajuste_data!$D$2:$D$49,">="&$E$4,regras_reajuste_data!$B$2:$B$49,"ativo")) -> 0 | F6: Busca na aba regras_reajuste_data. | AA6: MD-008 | Filé mignon ao forno, ao molho madeira, vinho ou mostarda | R$ 80,00 | AB6: MD-008 | AC6: Sabores Principais | AD6: prato_principal | AE6: por pessoa | AF6: 80 | AG6: pessoa | AH6: Filé mignon ao forno, ao molho madeira, vinho ou mostarda | AI6: Adicional real
A7: Desconto autorizado % | B7: 0 | C7: Campo admin. Use 0 se não houver desconto. | D7: Equipe extra | E7: =IFERROR(LOOKUP($B$4,regras_equipe!$C$2:$C$50,regras_equipe!$I$2:$I$50),0) -> 0 | F7: Busca na aba regras_equipe conforme convidados. | AA7: MD-009 | Lagarto ao molho madeira ou ervas | R$ 50,00 | AB7: MD-009 | AC7: Sabores Principais | AD7: prato_principal | AE7: por pessoa | AF7: 50 | AG7: pessoa | AH7: Lagarto ao molho madeira ou ervas | AI7: Adicional real
A8: Desconto autorizado R$ | B8: 0 | C8: Campo admin. Use 0 se não houver desconto. | D8: Valor mínimo ajustado | E8: =$B$14*$E$5 -> 25916 | F8: Valor mínimo do período x multiplicador da data. | AA8: MD-010 | Maminha ao molho barbecue ou madeira | R$ 55,00 | AB8: MD-010 | AC8: Sabores Principais | AD8: prato_principal | AE8: por pessoa | AF8: 55 | AG8: pessoa | AH8: Maminha ao molho barbecue ou madeira | AI8: Adicional real
A9: Incremento autorizado R$ | B9: 0 | C9: Campo admin. Use para ajuste especial autorizado. | D9: Subtotal antes do reajuste | E9: =IF($B$18="SIM",$B$16+$B$17+$E$7+$B$9,"") -> 22900 | F9: Base calculada + itens + equipe extra + incremento admin. | AA9: MD-011 | Lombo suíno ao molho agridoce ou abacaxi | R$ 35,00 | AB9: MD-011 | AC9: Sabores Principais | AD9: prato_principal | AE9: por pessoa | AF9: 35 | AG9: pessoa | AH9: Lombo suíno ao molho agridoce ou abacaxi | AI9: Adicional real
A10: Ajuste base por pessoa | B10: 0 | C10: Use se precisar complementar a base inclusa por pessoa. | D10: Subtotal reajustado | E10: =IF($B$18="SIM",$E$9*$E$5+$E$6,"") -> 28396 | F10: Subtotal antes do reajuste x multiplicador + acréscimo fixo. | AA10: MD-012 | Pernil ao molho barbecue | R$ 35,00 | AB10: MD-012 | AC10: Sabores Principais | AD10: prato_principal | AE10: por pessoa | AF10: 35 | AG10: pessoa | AH10: Pernil ao molho barbecue | AI10: Adicional real
A11: Base fixa do período | B11: =IFERROR(VLOOKUP($E$16,regras_periodo!$A$2:$M$9,8,FALSE),0) -> 12330 | C11: Busca na aba regras_periodo. | D11: Total após desconto | E11: =IF($B$18="SIM",$E$10-$B$20,"") -> 28396 | F11: Subtotal reajustado - descontos. | AA11: MD-013 | Filé de frango ao molho branco, ervas, queijo, mostarda ou madeira, molho de laranja ou limão siciliano | R$ 33,00 | AB11: MD-013 | AC11: Sabores Principais | AD11: prato_principal | AE11: por pessoa | AF11: 33 | AG11: pessoa | AH11: Filé de frango ao molho branco, ervas, queijo, mostarda ou madeira, molho de laranja ou limão siciliano | AI11: Adicional real
A12: Multiplicador do período | B12: =IFERROR(VLOOKUP($E$16,regras_periodo!$A$2:$M$9,9,FALSE),1) -> 1 | C12: Busca na aba regras_periodo. | D12: Regra equipe aplicada | E12: =IFERROR(LOOKUP($B$4,regras_equipe!$C$2:$C$50,regras_equipe!$E$2:$E$50),"") -> Equipe base | F12: Faixa automática pela quantidade de convidados. | AA12: MD-014 | Filé de coxa e sobrecoxa assada | R$ 30,00 | AB12: MD-014 | AC12: Sabores Principais | AD12: prato_principal | AE12: por pessoa | AF12: 30 | AG12: pessoa | AH12: Filé de coxa e sobrecoxa assada | AI12: Adicional real
A13: Acréscimo fixo do período | B13: =IFERROR(VLOOKUP($E$16,regras_periodo!$A$2:$M$9,10,FALSE),0) -> 0 | C13: Busca na aba regras_periodo. | D13: Regra data aplicada | E13: {=IF($E$4="","",IFERROR(INDEX(regras_reajuste_data!$E$2:$E$49,MATCH(1,($E$4>=regras_reajuste_data!$C$2:$C$49)*($E$4<=regras_reajuste_data!$D$2:$D$49)*(regras_reajuste_data!$B$2:$B$49="ativo"),0)),"sem regra"))} -> 1º semestre | F13: Semestre automático pela data informada. | AA13: MD-015 | Strogonoff de Frango, Batata Palha | R$ 30,00 | AB13: MD-015 | AC13: Sabores Principais | AD13: prato_principal | AE13: por pessoa | AF13: 30 | AG13: pessoa | AH13: Strogonoff de Frango, Batata Palha | AI13: Adicional real
A14: Valor mínimo do evento | B14: =IFERROR(VLOOKUP($E$16,regras_periodo!$A$2:$M$9,11,FALSE),0) -> 20900 | C14: Busca na aba regras_periodo. | D14: Dia da semana | E14: =IF($E$4="","",CHOOSE(WEEKDAY($E$4,2),"segunda-feira","terça-feira","quarta-feira","quinta-feira","sexta-feira","sábado","domingo")) -> sexta-feira | F14: Mostra o dia real da data informada. Feriado/véspera continuam tratados na regra comercial. | AA14: MD-016 | Salmão ao molho de maracujá ou alcaparras | R$ 80,00 | AB14: MD-016 | AC14: Sabores Principais | AD14: prato_principal | AE14: por pessoa | AF14: 80 | AG14: pessoa | AH14: Salmão ao molho de maracujá ou alcaparras | AI14: Adicional real
A15: Base inclusa por pessoa | B15: =SUM(base_inclusa!$E$2:$E$9)+$B$10 -> 55.7 | C15: Soma dos itens Incluso na base da aba base_inclusa. | D15: Período comercial | E15: =IFERROR(VLOOKUP($B$5,regras_periodo!$A$2:$M$9,5,FALSE),"manhã") -> noite | F15: Mantém o período da regra selecionada em B5. | AA15: MD-017 | Tilápia ao molho de alcaparras ou pimentão e cebola | R$ 40,00 | AB15: MD-017 | AC15: Sabores Principais | AD15: prato_principal | AE15: por pessoa | AF15: 40 | AG15: pessoa | AH15: Tilápia ao molho de alcaparras ou pimentão e cebola | AI15: Adicional real
A16: Base calculada | B16: =($B$11*$B$12)+$B$13+(($B$15)*$B$4)+IF($B$6="SIM",IFERROR(VLOOKUP($E$16,regras_periodo!$A$2:$M$9,12,FALSE),0),0) -> 17900 | C16: Base fixa ajustada + base por pessoa x convidados + exclusividade. Não inclui equipe extra nem reajuste por data. | D16: Regra comercial aplicada | E16: {=IF(OR($E$4="",$E$15=""),$B$5,LET(_diaCom,IFERROR(VLOOKUP($E$4,feriados!$A:$G,6,FALSE),CHOOSE(WEEKDAY($E$4,2),"segunda-quinta","segunda-quinta","segunda-quinta","segunda-quinta","sexta","sábado","domingo")),_diaCom2,IF(_diaCom="sabado","sábado",_diaCom),XLOOKUP(_diaCom2&"|"&$E$15&"|ativo",regras_periodo!$N$2:$N$9,regras_periodo!$A$2:$A$9,$B$5,0)))} -> REG-004 | F16: Regra final usada nos cálculos após considerar feriado/véspera. | AA16: MD-018 | Ceviche de tilápia | R$ 40,00 | AB16: MD-018 | AC16: Sabores Principais | AD16: prato_principal | AE16: por pessoa | AF16: 40 | AG16: pessoa | AH16: Ceviche de tilápia | AI16: Adicional real
A17: Total itens selecionados | B17: =SUM(J26:J65) -> 5000 | C17: Soma da tabela de seleção abaixo. | AA17: MD-019 | Bobó de camarão | R$ 60,00 | AB17: MD-019 | AC17: Sabores Principais | AD17: prato_principal | AE17: por pessoa | AF17: 60 | AG17: pessoa | AH17: Bobó de camarão | AI17: Adicional real
A18: Prato principal selecionado? | B18: =IF(COUNTIF($E$26:$E$65,"prato_principal")>0,"SIM","NÃO") -> SIM | C18: O total final só aparece se houver ao menos 1 prato principal. | AA18: MD-020 | Saint Peter gratinado | R$ 50,00 | AB18: MD-020 | AC18: Sabores Principais | AD18: prato_principal | AE18: por pessoa | AF18: 50 | AG18: pessoa | AH18: Saint Peter gratinado | AI18: Adicional real
A19: Subtotal antes do reajuste | B19: =IF($B$18="SIM",$B$16+$B$17+$E$7+$B$9,"") -> 22900 | C19: Base calculada + itens selecionados + equipe extra + incremento admin, antes do reajuste por data. | AA19: MD-021 | Batata frita, gratinada, rústica ou sauté | R$ 6,00 | AB19: MD-021 | AC19: Sabores Principais | AD19: personalizacao | AE19: por pessoa | AF19: 6 | AG19: pessoa | AH19: Batata frita, gratinada, rústica ou sauté | AI19: Adicional real
A20: Desconto calculado | B20: =IF($B$18="SIM",($E$10*$B$7)+$B$8,"") -> 0 | C20: Desconto aplicado sobre o subtotal já reajustado pela data. | AA20: MD-022 | Farofa com bacon e farinha de milho | R$ 3,00 | AB20: MD-022 | AC20: Sabores Principais | AD20: personalizacao | AE20: por pessoa | AF20: 3 | AG20: pessoa | AH20: Farofa com bacon e farinha de milho | AI20: Adicional real
A21: Total antes do mínimo | B21: =IF($B$18="SIM",$E$10-$B$20,"") -> 28396 | C21: Subtotal reajustado menos descontos autorizados. | AA21: MD-024 | Saladas: Maionese de legumes, Legumes salteados na manteiga. | R$ 5,00 | AB21: MD-024 | AC21: Sabores Principais | AD21: personalizacao | AE21: por pessoa | AF21: 5 | AG21: pessoa | AH21: Saladas: Maionese de legumes, Legumes salteados na manteiga. | AI21: Adicional real
A22: TOTAL FINAL | B22: =IF($B$18<>"SIM","",MAX($B$21,$E$8)) -> 28396 | C22: Maior entre total após desconto e valor mínimo ajustado pela data. | AA22: MD-025 | Salada Caesar, Caponata de Berinjela, Salpicão, Salada Califórnia, Maionese de legumes, Legumes salteados na manteiga. | R$ 10,00 | AB22: MD-025 | AC22: Sabores Principais | AD22: personalizacao | AE22: por pessoa | AF22: 10 | AG22: pessoa | AH22: Salada Caesar, Caponata de Berinjela, Salpicão, Salada Califórnia, Maionese de legumes, Legumes salteados na manteiga. | AI22: Adicional real
A23: Aviso | B23: =IF($B$18<>"SIM","Selecione pelo menos 1 prato principal para visualizar o total final.","OK") -> OK | AA23: MD-026 | Bisteca, Arroz carreteiro, Feijão tropeiro, Couve refogada, Torresmo | R$ 40,00 | AB23: MD-026 | AC23: Culinária Típica | AD23: personalizacao | AE23: por pessoa | AF23: 40 | AG23: pessoa | AH23: Bisteca, Arroz carreteiro, Feijão tropeiro, Couve refogada, Torresmo | AI23: Adicional real
AA24: MD-027 | Bisteca, Arroz carreteiro, Feijão tropeiro, Couve refogada, Torresmo, Polenta, Farofa de banana | R$ 45,00 | AB24: MD-027 | AC24: Culinária Típica | AD24: personalizacao | AE24: por pessoa | AF24: 45 | AG24: pessoa | AH24: Bisteca, Arroz carreteiro, Feijão tropeiro, Couve refogada, Torresmo, Polenta, Farofa de banana | AI24: Adicional real
A25: Nº | B25: Selecione o item | C25: Código | D25: Fase | E25: Grupo | F25: Cobrança | G25: Preço unitário | H25: Qtd manual | I25: Qtd usada | J25: Total | K25: Observação | L25: Prato principal? | AA25: MD-028 | Galinhada, Bisteca, Tutu de feijão, Arroz carreteiro, Feijão tropeiro, Couve refogada, Torresmo, Polenta cremosa, Farofa de banana | R$ 60,00 | AB25: MD-028 | AC25: Culinária Típica | AD25: personalizacao | AE25: por pessoa | AF25: 60 | AG25: pessoa | AH25: Galinhada, Bisteca, Tutu de feijão, Arroz carreteiro, Feijão tropeiro, Couve refogada, Torresmo, Polenta cremosa, Farofa de banana | AI25: Adicional real
A26: 1 | B26: MD-009 | Lagarto ao molho madeira ou ervas | R$ 50,00 | C26: =IFERROR(INDEX($AB$2:$AB$200,MATCH($B26,$AA$2:$AA$200,0)),"") -> MD-009 | D26: =IFERROR(INDEX($AC$2:$AC$200,MATCH($B26,$AA$2:$AA$200,0)),"") -> Sabores Principais | E26: =IFERROR(INDEX($AD$2:$AD$200,MATCH($B26,$AA$2:$AA$200,0)),"") -> prato_principal | F26: =IFERROR(INDEX($AE$2:$AE$200,MATCH($B26,$AA$2:$AA$200,0)),"") -> por pessoa | G26: =IFERROR(INDEX($AF$2:$AF$200,MATCH($B26,$AA$2:$AA$200,0)),0) -> 50 | I26: =IF($B26="","",IF($F26="por pessoa",$B$4,IF($F26="por evento",1,IF($H26<>"",$H26,1)))) -> 100 | J26: =IF($B26="","",$G26*$I26) -> 5000 | K26: =IF($B26="","",IF(OR($F26="por garrafa",$F26="por litro/barril"),"Preencha a qtd manual se for mais de 1.","")) | L26: =IF($B26="","",IFERROR(INDEX($AJ$2:$AJ$200,MATCH($B26,$AA$2:$AA$200,0)),"NÃO")) | AA26: MD-029 | Espeto de tofu marinado, espeto de legumes grelhados, churrasco vegetal, strogonoff de grão-de-bico, batata assada vegana e moqueca de banana-da-terra. | R$ 110,00 | AB26: MD-029 | AC26: Culinária Típica | AD26: personalizacao | AE26: por pessoa | AF26: 110 | AG26: pessoa | AH26: Espeto de tofu marinado, espeto de legumes grelhados, churrasco vegetal, strogonoff de grão-de-bico, batata assada vegana e moqueca de banana-da-terra. | AI26: Adicional real
A27: 2 | C27: =IFERROR(INDEX($AB$2:$AB$200,MATCH($B27,$AA$2:$AA$200,0)),"") | D27: =IFERROR(INDEX($AC$2:$AC$200,MATCH($B27,$AA$2:$AA$200,0)),"") | E27: =IFERROR(INDEX($AD$2:$AD$200,MATCH($B27,$AA$2:$AA$200,0)),"") | F27: =IFERROR(INDEX($AE$2:$AE$200,MATCH($B27,$AA$2:$AA$200,0)),"") | G27: =IFERROR(INDEX($AF$2:$AF$200,MATCH($B27,$AA$2:$AA$200,0)),0) -> 0 | I27: =IF($B27="","",IF($F27="por pessoa",$B$4,IF($F27="por evento",1,IF($H27<>"",$H27,1)))) | J27: =IF($B27="","",$G27*$I27) | K27: =IF($B27="","",IF(OR($F27="por garrafa",$F27="por litro/barril"),"Preencha a qtd manual se for mais de 1.","")) | L27: =IF($B27="","",IFERROR(INDEX($AJ$2:$AJ$200,MATCH($B27,$AA$2:$AA$200,0)),"NÃO")) | AA27: MD-030 | Estação de crepes | R$ 0,00 | AB27: MD-030 | AC27: Culinária Típica | AD27: massas_estacoes | AE27: por pessoa | AF27: 0 | AG27: pessoa | AH27: Estação de crepes | AI27: Adicional real
A28: 3 | C28: =IFERROR(INDEX($AB$2:$AB$200,MATCH($B28,$AA$2:$AA$200,0)),"") | D28: =IFERROR(INDEX($AC$2:$AC$200,MATCH($B28,$AA$2:$AA$200,0)),"") | E28: =IFERROR(INDEX($AD$2:$AD$200,MATCH($B28,$AA$2:$AA$200,0)),"") | F28: =IFERROR(INDEX($AE$2:$AE$200,MATCH($B28,$AA$2:$AA$200,0)),"") | G28: =IFERROR(INDEX($AF$2:$AF$200,MATCH($B28,$AA$2:$AA$200,0)),0) -> 0 | I28: =IF($B28="","",IF($F28="por pessoa",$B$4,IF($F28="por evento",1,IF($H28<>"",$H28,1)))) | J28: =IF($B28="","",$G28*$I28) | K28: =IF($B28="","",IF(OR($F28="por garrafa",$F28="por litro/barril"),"Preencha a qtd manual se for mais de 1.","")) | L28: =IF($B28="","",IFERROR(INDEX($AJ$2:$AJ$200,MATCH($B28,$AA$2:$AA$200,0)),"NÃO")) | AA28: MD-031 | Ilha árabe | R$ 0,00 | AB28: MD-031 | AC28: Culinária Típica | AD28: massas_estacoes | AE28: por pessoa | AF28: 0 | AG28: pessoa | AH28: Ilha árabe | AI28: Adicional real
A29: 4 | C29: =IFERROR(INDEX($AB$2:$AB$200,MATCH($B29,$AA$2:$AA$200,0)),"") | D29: =IFERROR(INDEX($AC$2:$AC$200,MATCH($B29,$AA$2:$AA$200,0)),"") | E29: =IFERROR(INDEX($AD$2:$AD$200,MATCH($B29,$AA$2:$AA$200,0)),"") | F29: =IFERROR(INDEX($AE$2:$AE$200,MATCH($B29,$AA$2:$AA$200,0)),"") | G29: =IFERROR(INDEX($AF$2:$AF$200,MATCH($B29,$AA$2:$AA$200,0)),0) -> 0 | I29: =IF($B29="","",IF($F29="por pessoa",$B$4,IF($F29="por evento",1,IF($H29<>"",$H29,1)))) | J29: =IF($B29="","",$G29*$I29) | K29: =IF($B29="","",IF(OR($F29="por garrafa",$F29="por litro/barril"),"Preencha a qtd manual se for mais de 1.","")) | L29: =IF($B29="","",IFERROR(INDEX($AJ$2:$AJ$200,MATCH($B29,$AA$2:$AA$200,0)),"NÃO")) | AA29: MD-032 | Ilha japonesa | R$ 0,00 | AB29: MD-032 | AC29: Culinária Típica | AD29: massas_estacoes | AE29: por pessoa | AF29: 0 | AG29: pessoa | AH29: Ilha japonesa | AI29: Adicional real
A30: 5 | C30: =IFERROR(INDEX($AB$2:$AB$200,MATCH($B30,$AA$2:$AA$200,0)),"") | D30: =IFERROR(INDEX($AC$2:$AC$200,MATCH($B30,$AA$2:$AA$200,0)),"") | E30: =IFERROR(INDEX($AD$2:$AD$200,MATCH($B30,$AA$2:$AA$200,0)),"") | F30: =IFERROR(INDEX($AE$2:$AE$200,MATCH($B30,$AA$2:$AA$200,0)),"") | G30: =IFERROR(INDEX($AF$2:$AF$200,MATCH($B30,$AA$2:$AA$200,0)),0) -> 0 | I30: =IF($B30="","",IF($F30="por pessoa",$B$4,IF($F30="por evento",1,IF($H30<>"",$H30,1)))) | J30: =IF($B30="","",$G30*$I30) | K30: =IF($B30="","",IF(OR($F30="por garrafa",$F30="por litro/barril"),"Preencha a qtd manual se for mais de 1.","")) | L30: =IF($B30="","",IFERROR(INDEX($AJ$2:$AJ$200,MATCH($B30,$AA$2:$AA$200,0)),"NÃO")) | AA30: MD-033 | Ilha mexicana | R$ 0,00 | AB30: MD-033 | AC30: Culinária Típica | AD30: massas_estacoes | AE30: por pessoa | AF30: 0 | AG30: pessoa | AH30: Ilha mexicana | AI30: Adicional real
A31: 6 | C31: =IFERROR(INDEX($AB$2:$AB$200,MATCH($B31,$AA$2:$AA$200,0)),"") | D31: =IFERROR(INDEX($AC$2:$AC$200,MATCH($B31,$AA$2:$AA$200,0)),"") | E31: =IFERROR(INDEX($AD$2:$AD$200,MATCH($B31,$AA$2:$AA$200,0)),"") | F31: =IFERROR(INDEX($AE$2:$AE$200,MATCH($B31,$AA$2:$AA$200,0)),"") | G31: =IFERROR(INDEX($AF$2:$AF$200,MATCH($B31,$AA$2:$AA$200,0)),0) -> 0 | I31: =IF($B31="","",IF($F31="por pessoa",$B$4,IF($F31="por evento",1,IF($H31<>"",$H31,1)))) | J31: =IF($B31="","",$G31*$I31) | K31: =IF($B31="","",IF(OR($F31="por garrafa",$F31="por litro/barril"),"Preencha a qtd manual se for mais de 1.","")) | L31: =IF($B31="","",IFERROR(INDEX($AJ$2:$AJ$200,MATCH($B31,$AA$2:$AA$200,0)),"NÃO")) | AA31: MD-034 | Contra filé, linguiça e frango | R$ 65,00 | AB31: MD-034 | AC31: Brasa Margô | AD31: prato_principal | AE31: por pessoa | AF31: 65 | AG31: pessoa | AH31: Contra filé, linguiça e frango | AI31: Adicional real
A32: 7 | C32: =IFERROR(INDEX($AB$2:$AB$200,MATCH($B32,$AA$2:$AA$200,0)),"") | D32: =IFERROR(INDEX($AC$2:$AC$200,MATCH($B32,$AA$2:$AA$200,0)),"") | E32: =IFERROR(INDEX($AD$2:$AD$200,MATCH($B32,$AA$2:$AA$200,0)),"") | F32: =IFERROR(INDEX($AE$2:$AE$200,MATCH($B32,$AA$2:$AA$200,0)),"") | G32: =IFERROR(INDEX($AF$2:$AF$200,MATCH($B32,$AA$2:$AA$200,0)),0) -> 0 | I32: =IF($B32="","",IF($F32="por pessoa",$B$4,IF($F32="por evento",1,IF($H32<>"",$H32,1)))) | J32: =IF($B32="","",$G32*$I32) | K32: =IF($B32="","",IF(OR($F32="por garrafa",$F32="por litro/barril"),"Preencha a qtd manual se for mais de 1.","")) | L32: =IF($B32="","",IFERROR(INDEX($AJ$2:$AJ$200,MATCH($B32,$AA$2:$AA$200,0)),"NÃO")) | AA32: MD-035 | Contra filé, linguiça, filé de coxa e sobrecoxa, maminha na manteiga e cupim | R$ 80,00 | AB32: MD-035 | AC32: Brasa Margô | AD32: prato_principal | AE32: por pessoa | AF32: 80 | AG32: pessoa | AH32: Contra filé, linguiça, filé de coxa e sobrecoxa, maminha na manteiga e cupim | AI32: Adicional real
A33: 8 | C33: =IFERROR(INDEX($AB$2:$AB$200,MATCH($B33,$AA$2:$AA$200,0)),"") | D33: =IFERROR(INDEX($AC$2:$AC$200,MATCH($B33,$AA$2:$AA$200,0)),"") | E33: =IFERROR(INDEX($AD$2:$AD$200,MATCH($B33,$AA$2:$AA$200,0)),"") | F33: =IFERROR(INDEX($AE$2:$AE$200,MATCH($B33,$AA$2:$AA$200,0)),"") | G33: =IFERROR(INDEX($AF$2:$AF$200,MATCH($B33,$AA$2:$AA$200,0)),0) -> 0 | I33: =IF($B33="","",IF($F33="por pessoa",$B$4,IF($F33="por evento",1,IF($H33<>"",$H33,1)))) | J33: =IF($B33="","",$G33*$I33) | K33: =IF($B33="","",IF(OR($F33="por garrafa",$F33="por litro/barril"),"Preencha a qtd manual se for mais de 1.","")) | L33: =IF($B33="","",IFERROR(INDEX($AJ$2:$AJ$200,MATCH($B33,$AA$2:$AA$200,0)),"NÃO")) | AA33: MD-036 | Costela bovina, Contra filé, linguiça, filé de coxa e sobrecoxa, maminha na manteiga, cupim, picanha e panceta | R$ 160,00 | AB33: MD-036 | AC33: Brasa Margô | AD33: prato_principal | AE33: por pessoa | AF33: 160 | AG33: pessoa | AH33: Costela bovina, Contra filé, linguiça, filé de coxa e sobrecoxa, maminha na manteiga, cupim, picanha e panceta | AI33: Adicional real
A34: 9 | C34: =IFERROR(INDEX($AB$2:$AB$200,MATCH($B34,$AA$2:$AA$200,0)),"") | D34: =IFERROR(INDEX($AC$2:$AC$200,MATCH($B34,$AA$2:$AA$200,0)),"") | E34: =IFERROR(INDEX($AD$2:$AD$200,MATCH($B34,$AA$2:$AA$200,0)),"") | F34: =IFERROR(INDEX($AE$2:$AE$200,MATCH($B34,$AA$2:$AA$200,0)),"") | G34: =IFERROR(INDEX($AF$2:$AF$200,MATCH($B34,$AA$2:$AA$200,0)),0) -> 0 | I34: =IF($B34="","",IF($F34="por pessoa",$B$4,IF($F34="por evento",1,IF($H34<>"",$H34,1)))) | J34: =IF($B34="","",$G34*$I34) | K34: =IF($B34="","",IF(OR($F34="por garrafa",$F34="por litro/barril"),"Preencha a qtd manual se for mais de 1.","")) | L34: =IF($B34="","",IFERROR(INDEX($AJ$2:$AJ$200,MATCH($B34,$AA$2:$AA$200,0)),"NÃO")) | AA34: MD-037 | Kafta, Pão de alho, Coração | R$ 12,00 | AB34: MD-037 | AC34: Brasa Margô | AD34: brasa_complemento | AE34: por pessoa | AF34: 12 | AG34: pessoa | AH34: Kafta, Pão de alho, Coração | AI34: Adicional real
A35: 10 | C35: =IFERROR(INDEX($AB$2:$AB$200,MATCH($B35,$AA$2:$AA$200,0)),"") | D35: =IFERROR(INDEX($AC$2:$AC$200,MATCH($B35,$AA$2:$AA$200,0)),"") | E35: =IFERROR(INDEX($AD$2:$AD$200,MATCH($B35,$AA$2:$AA$200,0)),"") | F35: =IFERROR(INDEX($AE$2:$AE$200,MATCH($B35,$AA$2:$AA$200,0)),"") | G35: =IFERROR(INDEX($AF$2:$AF$200,MATCH($B35,$AA$2:$AA$200,0)),0) -> 0 | I35: =IF($B35="","",IF($F35="por pessoa",$B$4,IF($F35="por evento",1,IF($H35<>"",$H35,1)))) | J35: =IF($B35="","",$G35*$I35) | K35: =IF($B35="","",IF(OR($F35="por garrafa",$F35="por litro/barril"),"Preencha a qtd manual se for mais de 1.","")) | L35: =IF($B35="","",IFERROR(INDEX($AJ$2:$AJ$200,MATCH($B35,$AA$2:$AA$200,0)),"NÃO")) | AA35: MD-038 | Tulipa, Kafta, Pão de queijo, Pão de alho, Coração | R$ 15,00 | AB35: MD-038 | AC35: Brasa Margô | AD35: brasa_complemento | AE35: por pessoa | AF35: 15 | AG35: pessoa | AH35: Tulipa, Kafta, Pão de queijo, Pão de alho, Coração | AI35: Adicional real
A36: 11 | C36: =IFERROR(INDEX($AB$2:$AB$200,MATCH($B36,$AA$2:$AA$200,0)),"") | D36: =IFERROR(INDEX($AC$2:$AC$200,MATCH($B36,$AA$2:$AA$200,0)),"") | E36: =IFERROR(INDEX($AD$2:$AD$200,MATCH($B36,$AA$2:$AA$200,0)),"") | F36: =IFERROR(INDEX($AE$2:$AE$200,MATCH($B36,$AA$2:$AA$200,0)),"") | G36: =IFERROR(INDEX($AF$2:$AF$200,MATCH($B36,$AA$2:$AA$200,0)),0) -> 0 | I36: =IF($B36="","",IF($F36="por pessoa",$B$4,IF($F36="por evento",1,IF($H36<>"",$H36,1)))) | J36: =IF($B36="","",$G36*$I36) | K36: =IF($B36="","",IF(OR($F36="por garrafa",$F36="por litro/barril"),"Preencha a qtd manual se for mais de 1.","")) | L36: =IF($B36="","",IFERROR(INDEX($AJ$2:$AJ$200,MATCH($B36,$AA$2:$AA$200,0)),"NÃO")) | AA36: MD-039 | Tulipa, Queijo coalho, Kafta, Pão de queijo, Pão de alho, Coração | R$ 17,00 | AB36: MD-039 | AC36: Brasa Margô | AD36: brasa_complemento | AE36: por pessoa | AF36: 17 | AG36: pessoa | AH36: Tulipa, Queijo coalho, Kafta, Pão de queijo, Pão de alho, Coração | AI36: Adicional real
A37: 12 | C37: =IFERROR(INDEX($AB$2:$AB$200,MATCH($B37,$AA$2:$AA$200,0)),"") | D37: =IFERROR(INDEX($AC$2:$AC$200,MATCH($B37,$AA$2:$AA$200,0)),"") | E37: =IFERROR(INDEX($AD$2:$AD$200,MATCH($B37,$AA$2:$AA$200,0)),"") | F37: =IFERROR(INDEX($AE$2:$AE$200,MATCH($B37,$AA$2:$AA$200,0)),"") | G37: =IFERROR(INDEX($AF$2:$AF$200,MATCH($B37,$AA$2:$AA$200,0)),0) -> 0 | I37: =IF($B37="","",IF($F37="por pessoa",$B$4,IF($F37="por evento",1,IF($H37<>"",$H37,1)))) | J37: =IF($B37="","",$G37*$I37) | K37: =IF($B37="","",IF(OR($F37="por garrafa",$F37="por litro/barril"),"Preencha a qtd manual se for mais de 1.","")) | L37: =IF($B37="","",IFERROR(INDEX($AJ$2:$AJ$200,MATCH($B37,$AA$2:$AA$200,0)),"NÃO")) | AA37: MD-040 | Costelinha suína barbecue | R$ 17,00 | AB37: MD-040 | AC37: Brasa Margô | AD37: brasa_complemento | AE37: por pessoa | AF37: 17 | AG37: pessoa | AH37: Costelinha suína barbecue | AI37: Adicional real
A38: 13 | C38: =IFERROR(INDEX($AB$2:$AB$200,MATCH($B38,$AA$2:$AA$200,0)),"") | D38: =IFERROR(INDEX($AC$2:$AC$200,MATCH($B38,$AA$2:$AA$200,0)),"") | E38: =IFERROR(INDEX($AD$2:$AD$200,MATCH($B38,$AA$2:$AA$200,0)),"") | F38: =IFERROR(INDEX($AE$2:$AE$200,MATCH($B38,$AA$2:$AA$200,0)),"") | G38: =IFERROR(INDEX($AF$2:$AF$200,MATCH($B38,$AA$2:$AA$200,0)),0) -> 0 | I38: =IF($B38="","",IF($F38="por pessoa",$B$4,IF($F38="por evento",1,IF($H38<>"",$H38,1)))) | J38: =IF($B38="","",$G38*$I38) | K38: =IF($B38="","",IF(OR($F38="por garrafa",$F38="por litro/barril"),"Preencha a qtd manual se for mais de 1.","")) | L38: =IF($B38="","",IFERROR(INDEX($AJ$2:$AJ$200,MATCH($B38,$AA$2:$AA$200,0)),"NÃO")) | AA38: MD-041 | Nhoque ao sugo, Massa ao molho de tomate fresco, Fettuccine ao molho branco ou ervas, Lasanha de frango | R$ 70,00 | AB38: MD-041 | AC38: Massas & Estações | AD38: massas_estacoes | AE38: por pessoa | AF38: 70 | AG38: pessoa | AH38: Nhoque ao sugo, Massa ao molho de tomate fresco, Fettuccine ao molho branco ou ervas, Lasanha de frango | AI38: Adicional real
... A65: 40 | C65: =IFERROR(INDEX($AB$2:$AB$200,MATCH($B65,$AA$2:$AA$200,0)),"") | D65: =IFERROR(INDEX($AC$2:$AC$200,MATCH($B65,$AA$2:$AA$200,0)),"") | E65: =IFERROR(INDEX($AD$2:$AD$200,MATCH($B65,$AA$2:$AA$200,0)),"") | F65: =IFERROR(INDEX($AE$2:$AE$200,MATCH($B65,$AA$2:$AA$200,0)),"") | G65: =IFERROR(INDEX($AF$2:$AF$200,MATCH($B65,$AA$2:$AA$200,0)),0) -> 0 | I65: =IF($B65="","",IF($F65="por pessoa",$B$4,IF($F65="por evento",1,IF($H65<>"",$H65,1)))) | J65: =IF($B65="","",$G65*$I65) | K65: =IF($B65="","",IF(OR($F65="por garrafa",$F65="por litro/barril"),"Preencha a qtd manual se for mais de 1.","")) | L65: =IF($B65="","",IFERROR(INDEX($AJ$2:$AJ$200,MATCH($B65,$AA$2:$AA$200,0)),"NÃO")) | AA65: MD-072 | Pista de dança Paris LED | R$ 1.120,00 | AB65: MD-072 | AC65: Experiência | AD65: encantamentos | AE65: por evento | AF65: 1120 | AG65: evento | AH65: Pista de dança Paris LED | AI65: Adicional real
AA66: MD-073 | Plataforma 360 | R$ 910,00 | AB66: MD-073 | AC66: Experiência | AD66: encantamentos | AE66: por evento | AF66: 910 | AG66: evento | AH66: Plataforma 360 | AI66: Adicional real
...

Sheet itens_proposta
A1: item_proposta_id | B1: tipo_proposta | C1: opcao | D1: categoria | E1: codigo_item | F1: status | G1: ordem_exibicao | H1: observacao | I1: atualizado_em
A2: IP001 | B2: PADRAO | C2: 1 | D2: prato_principal | E2: MD-020 | F2: ATIVO | G2: 1 | H2: Opção 1 da proposta
A3: IP002 | B3: PADRAO | C3: 2 | D3: prato_principal | E3: MD-014 | F3: ATIVO | G3: 2 | H3: Opção 2 da proposta
A4: IP003 | B4: PADRAO | C4: 3 | D4: prato_principal | E4: MD-029 | F4: ATIVO | G4: 3 | H4: Opção 3 da proposta
A5: IP004 | B5: PADRAO | C5: 4 | D5: prato_principal | E5: MD-036 | F5: ATIVO | G5: 4 | H5: Opção 4 da proposta

Sheet itens_modulares
B1: ordem_fase | C1: fase | D1: card | E1: categoria | F1: item | G1: caminho_sugerido | H1: tipo_item | I1: natureza_sugerida | J1: tipo_cobranca_sugerido | K1: unidade | L1: qtd_referencia | M1: custo_insumo | N1: custo_equipe | O1: custo_operacional | P1: perda_pct | Q1: custo_base | R1: custo_com_perda | S1: markup_sugerido | T1: preco_venda_sugerido | U1: preco_arredondado | V1: preco_manual | W1: preco_final | X1: margem_bruta_pct | Y1: status | Z1: observacoes | AA1: grupo_escolha | AB1: selecionado_padrao | AC1: incluido_no_preco_inicial | AD1: pode_remover | AE1: exige_substituto | AF1: minimo_grupo | AG1: maximo_grupo | AH1: obrigatorio_para_fechar | AI1: gera_desconto_ao_remover | AJ1: visivel_app | AK1: regra_total_app | AL1: regra_calculo_app | AM1: preco_final_num | AN1: custo_insumo_num | AO1: preco_display | AP1: eh_prato_principal | AQ1: Visivel no menu | AR1: descricao_atelie
A2: MD-001 | B2: 0 | C2: Antes e depois do sim | D2: incluso na base | E2: Base Principal | F2: Boas-vindas - Agua Saborizada, Refrigerantes, Canapés, Patês e Torradinhas | G2: Essencial | H2: Composição | I2: Incluso na base | J2: por evento | K2: pessoa | M2: 0 | P2: 10,0% | Q2: 0 | R2: 0 | S2: 0 | T2: 0 | U2: 0 | V2: 0 | W2: 0 | X2: 50,0% | Y2: ativo | AA2: base_evento | AB2: SIM | AC2: SIM | AD2: NÃO | AE2: NÃO | AH2: SIM | AI2: NÃO | AJ2: SIM | AK2: incluso_no_preco_inicial_nao_somar | AL2: Item fixo da Experiência Essencial. Exibir como incluso; não somar novamente e não permitir remoção. | AM2: 2.2 | AN2: 1 | AO2: R$ 2,20 | AP2: =IF($AA2="prato_principal","SIM","NÃO") -> NÃO | AQ2: NAO | AR2: Boas-vindas - Canapés, Patês e Torradinhas
A3: MD-002 | B3: 0 | C3: Antes e depois do sim | D3: incluso na base | E3: Base Principal | F3: Mini Salgados: Bolinho de carne, Mini coxinha, Mini risole de presunto, Mini risole de calabresa, Mini kibe, Polenta | G3: Essencial | H3: Composição | I3: Incluso na base | J3: por pessoa | K3: pessoa | M3: 0 | P3: 10,0% | Q3: 0 | R3: 0 | S3: 0 | T3: 0 | U3: 0 | V3: 0 | W3: 0 | X3: 1,0% | Y3: ativo | AA3: entradas | AB3: SIM | AC3: SIM | AD3: NÃO | AE3: NÃO | AH3: SIM | AI3: NÃO | AJ3: SIM | AK3: incluso_no_preco_inicial_nao_somar | AL3: Entradas essenciais inclusas. Exibir como incluso; não somar novamente e não permitir remoção. | AM3: 10 | AN3: 9 | AO3: R$ 10,00 | AP3: =IF($AA3="prato_principal","SIM","NÃO") -> NÃO | AQ3: NAO | AR3: Mini Salgados: Bolinho de carne, Mini coxinha, Mini risole de presunto, Mini risole de calabresa, Mini kibe, Polenta
A4: MD-003 | B4: 0 | C4: Doces & Cafés | D4: incluso na base | E4: Base Principal | F4: Bolo Massa Branca ou Chocolate c/ Recheio doce de leite com abacaxi, ameixa | G4: Essencial | H4: Composição | I4: Incluso na base | J4: por pessoa | K4: pessoa | M4: 0 | P4: 10,0% | Q4: 0 | R4: 0 | S4: 0 | T4: 0 | U4: 0 | V4: 0 | W4: 0 | X4: -65,0% | Y4: ativo | AA4: bolo_sorvete | AB4: SIM | AC4: SIM | AD4: NÃO | AE4: NÃO | AF4: 1 | AG4: 1 | AH4: SIM | AI4: NÃO | AJ4: SIM | AK4: incluso_no_preco_inicial_nao_somar | AL4: Bolo base incluso. Se houver upgrade, manter apenas 1 opção ativa no grupo bolo_sorvete. | AM4: 8 | AN4: 12 | AO4: R$ 8,00 | AP4: =IF($AA4="prato_principal","SIM","NÃO") -> NÃO | AQ4: NAO | AR4: Bolo Massa Branca ou Chocolate c/ Recheio doce de leite com abacaxi, ameixa
A5: MD-004 | B5: 0 | C5: Doces & Cafés | D5: incluso na base | E5: Base Principal | F5: Café, chá, biscoitos amanteigados | G5: Essencial | H5: Composição | I5: Incluso na base | J5: por pessoa | K5: pessoa | M5: 0 | P5: 10,0% | Q5: 0 | R5: 0 | S5: 3 | T5: 0 | U5: 0 | V5: 0 | W5: 0 | X5: 68,6% | Y5: ativo | AA5: brunch_encerramento | AB5: SIM | AC5: SIM | AD5: NÃO | AE5: NÃO | AH5: SIM | AI5: NÃO | AJ5: SIM | AK5: incluso_no_preco_inicial_nao_somar | AL5: Brunch essencial incluso. Exibir como incluso; não somar novamente e não permitir remoção. | AM5: 3.5 | AN5: 1 | AO5: R$ 3,50 | AP5: =IF($AA5="prato_principal","SIM","NÃO") -> NÃO | AQ5: NAO | AR5: Café, chá, biscoitos amanteigados
A6: MD-005 | B6: 0 | C6: Hora da Balada | D6: incluso na base | E6: Base Principal | F6: Refrigerantes 1a linha, light, diet, 2 tipos de suco de frutas natural | G6: Essencial | H6: Composição | I6: Incluso na base | J6: por pessoa | K6: pessoa | M6: 0 | P6: 3,0% | Q6: 0 | R6: 0 | S6: 0 | T6: 0 | U6: 0 | V6: 0 | W6: 0 | X6: 7,3% | Y6: ativo | AA6: base_evento | AB6: SIM | AC6: SIM | AD6: NÃO | AE6: NÃO | AH6: SIM | AI6: NÃO | AJ6: SIM | AK6: incluso_no_preco_inicial_nao_somar | AL6: Item fixo da Experiência Essencial. Exibir como incluso; não somar novamente e não permitir remoção. | AM6: 10 | AN6: 9 | AO6: R$ 10,00 | AP6: =IF($AA6="prato_principal","SIM","NÃO") -> NÃO | AQ6: NAO | AR6: Refrigerantes 1a linha, light, diet, 2 tipos de suco de frutas natural
A7: MD-006 | B7: 0 | C7: Massas & Saladas | D7: incluso na base | E7: Base Principal | F7: Espaguete à carbonara ou ao sugo | G7: Personalização | H7: Complemento | I7: Incluso na base | J7: por pessoa | K7: pessoa | M7: 0 | P7: 10,0% | Q7: 0 | R7: 0 | S7: 0 | T7: 0 | U7: 0 | V7: 0 | W7: 0 | X7: 72,5% | Y7: ativo | AA7: massas_estacoes | AB7: SIM | AC7: SIM | AD7: NAO | AE7: NÃO | AH7: SIM | AI7: NÃO | AJ7: SIM | AK7: somar_quando_selecionado | AL7: Estação, ilha ou massa individual. Somar ao total quando selecionado. | AM7: 10 | AN7: 2.5 | AO7: R$ 10,00 | AP7: =IF($AA7="prato_principal","SIM","NÃO") -> NÃO | AQ7: NAO | AR7: Espaguete à carbonara ou ao sugo
A8: MD-007 | B8: 0 | C8: Pratos Principais | D8: incluso na base | E8: Base Principal | F8: Arroz branco, arroz à grega ou arroz com brócolis e Feijão | G8: Essencial | H8: Composição | I8: Incluso na base | J8: por pessoa | K8: pessoa | M8: 0 | P8: 10,0% | Q8: 0 | R8: 0 | S8: 0 | T8: 0 | U8: 0 | V8: 0 | W8: 0 | X8: 56,0% | Y8: ativo | AA8: base_evento | AB8: SIM | AC8: SIM | AD8: NÃO | AE8: NÃO | AH8: SIM | AI8: NÃO | AJ8: SIM | AK8: incluso_no_preco_inicial_nao_somar | AL8: Item fixo da Experiência Essencial. Exibir como incluso; não somar novamente e não permitir remoção. | AM8: 5 | AN8: 2 | AO8: R$ 5,00 | AP8: =IF($AA8="prato_principal","SIM","NÃO") -> NÃO | AQ8: NAO | AR8: Arroz branco, arroz à grega ou arroz com brócolis e Feijão
A9: MD-008 | B9: 0 | C9: Saladas & Guarnições | D9: incluso na base | E9: Base Principal | F9: Saladas: mix de folhas, alface, rúcula, agrião, tomate, pepino, cebola | G9: Essencial | H9: Composição | I9: Incluso na base | J9: por pessoa | K9: pessoa | M9: R$ 3,00 | P9: 10,0% | Q9: R$ 3,00 | R9: R$ 3,30 | S9: 2,00 | T9: R$ 6,60 | U9: R$ 10,00 | V9: R$ 7,00 | W9: R$ 7,00 | X9: 52,9% | Y9: ativo | AA9: base_evento | AB9: SIM | AC9: SIM | AD9: NÃO | AE9: NÃO | AH9: SIM | AI9: NÃO | AJ9: SIM | AK9: incluso_no_preco_inicial_nao_somar | AL9: Item fixo da Experiência Essencial. Exibir como incluso; não somar novamente e não permitir remoção. | AM9: 7 | AN9: 3 | AO9: R$ 7,00 | AP9: =IF($AA9="prato_principal","SIM","NÃO") -> NÃO | AQ9: NAO | AR9: Saladas: mix de folhas, alface, rúcula, agrião, tomate, pepino, cebola
A10: MD-009 | B10: 1 | C10: Antes e depois do sim | D10: Welcome Drinks | E10: Cerimônia e Acolhimento | F10: Coqueteis de Frutas, suave para ir criando o clima de festa | G10: Personalização | H10: Serviço/Experiência | I10: Adicional real | J10: por pessoa | K10: pessoa | M10: R$ 2,00 | P10: 10,0% | Q10: R$ 2,00 | R10: R$ 2,20 | S10: 2,00 | T10: R$ 4,40 | U10: R$ 10,00 | V10: R$ 4,40 | W10: R$ 4,40 | X10: 50,0% | Y10: ativo | AA10: personalizacao | AB10: NÃO | AC10: NÃO | AD10: SIM | AE10: NÃO | AH10: NÃO | AI10: NÃO | AJ10: SIM | AK10: somar_quando_selecionado | AL10: Somar ao total quando selecionado. | AM10: 4.4 | AN10: 2 | AO10: R$ 4,40 | AP10: =IF($AA10="prato_principal","SIM","NÃO") -> NÃO | AQ10: SIM | AR10: Coqueteis de Frutas, suave para ir criando o clima de festa
A11: MD-010 | B11: 2 | C11: Antes e depois do sim | D11: Entradas Gourmet | E11: Entradas Gourmet I | F11: Bruschetta tradicional, Caponata italiana, Dadinho de tapioca, Croquete de carne, Espetinho caprese, Escondidinho de Carne/Calabresa | G11: Celebração | H11: Composição | I11: Adicional real | J11: por pessoa | K11: pessoa | M11: R$ 9,00 | P11: 10,0% | Q11: R$ 9,00 | R11: R$ 9,90 | S11: 1,50 | T11: R$ 14,85 | U11: R$ 20,00 | V11: R$ 14,00 | W11: R$ 14,00 | X11: 29,3% | Y11: ativo | AA11: entradas | AB11: NÃO | AC11: NÃO | AD11: SIM | AE11: NÃO | AH11: NÃO | AI11: NÃO | AJ11: SIM | AK11: somar_quando_selecionado | AL11: Acrescenta variedade às entradas essenciais. Somar ao total quando selecionado. | AM11: 14 | AN11: 9 | AO11: R$ 14,00 | AP11: =IF($AA11="prato_principal","SIM","NÃO") -> NÃO | AQ11: SIM | AR11: Bruschetta tradicional, Caponata italiana, Dadinho de tapioca, Croquete de carne, Espetinho caprese, Escondidinho de Carne/Calabresa
A12: MD-011 | B12: 3 | C12: Antes e depois do sim | D12: Entradas Premium | E12: Entradas Gourmet II | F12: Bolinho de bacalhau, Bruschetta de cogumelos, Canapés finos, Queijo Brie, Tábua de frios, Cuscus marroquino, Barquinha de salpicão, Escondidinho de Carne/Calabresa | G12: Premium | H12: Composição | I12: Adicional real | J12: por pessoa | K12: pessoa | M12: R$ 15,00 | P12: 10,0% | Q12: R$ 15,00 | R12: R$ 16,50 | S12: 1,50 | T12: R$ 24,75 | U12: R$ 30,00 | V12: R$ 25,00 | W12: R$ 25,00 | X12: 34,0% | Y12: ativo | AA12: entradas | AB12: NÃO | AC12: NÃO | AD12: SIM | AE12: NÃO | AH12: NÃO | AI12: NÃO | AJ12: SIM | AK12: somar_quando_selecionado | AL12: Acrescenta variedade às entradas essenciais. Somar ao total quando selecionado. | AM12: 25 | AN12: 15 | AO12: R$ 25,00 | AP12: =IF($AA12="prato_principal","SIM","NÃO") -> NÃO | AQ12: SIM | AR12: Bolinho de bacalhau, Bruschetta de cogumelos, Canapés finos, Queijo Brie, Tábua de frios, Cuscus marroquino, Barquinha de salpicão, Escondidinho de Carne/Calabresa
A13: MD-012 | B13: 4 | C13: Pratos Principais | D13: Carnes | E13: Carnes Bovinas | F13: Alcatra ao molho de manga | G13: Personalização | H13: Item avulso | I13: Adicional real | J13: por pessoa | K13: pessoa | M13: R$ 33,00 | P13: 10,0% | Q13: R$ 33,00 | R13: R$ 36,30 | S13: 1,50 | T13: R$ 54,45 | U13: R$ 60,00 | V13: R$ 55,00 | W13: R$ 55,00 | X13: 34,0% | Y13: ativo | Z13: Pode compor o prato principal do evento. Caso o Strogonoff padrão seja removido, este item assume como prato principal escolhido. | AA13: prato_principal | AB13: NÃO | AC13: NÃO | AD13: SIM | AE13: NÃO | AF13: 1 | AH13: NÃO | AI13: NÃO | AJ13: SIM | AK13: somar_quando_selecionado | AL13: Somar ao total quando selecionado. Pode substituir o Strogonoff padrão, sem desconto pela remoção do padrão. | AM13: 55 | AN13: 33 | AO13: R$ 55,00 | AP13: =IF($AA13="prato_principal","SIM","NÃO") -> SIM | AQ13: SIM | AR13: Alcatra ao molho de manga
A14: MD-013 | B14: 4 | C14: Pratos Principais | D14: Carnes | E14: Carnes Bovinas | F14: Filé mignon ao forno, ao molho madeira, vinho ou mostarda | G14: Personalização | H14: Item avulso | I14: Adicional real | J14: por pessoa | K14: pessoa | M14: R$ 45,00 | P14: 10,0% | Q14: R$ 45,00 | R14: R$ 49,50 | S14: 1,50 | T14: R$ 74,25 | U14: R$ 80,00 | V14: 80 | W14: R$ 80,00 | X14: 38,1% | Y14: ativo | Z14: Pode compor o prato principal do evento. Caso o Strogonoff padrão seja removido, este item assume como prato principal escolhido. | AA14: prato_principal | AB14: NÃO | AC14: NÃO | AD14: SIM | AE14: NÃO | AF14: 1 | AH14: NÃO | AI14: NÃO | AJ14: SIM | AK14: somar_quando_selecionado | AL14: Somar ao total quando selecionado. Pode substituir o Strogonoff padrão, sem desconto pela remoção do padrão. | AM14: 80 | AN14: 45 | AO14: R$ 80,00 | AP14: =IF($AA14="prato_principal","SIM","NÃO") -> SIM | AQ14: SIM | AR14: Filé mignon ao forno, ao molho madeira, vinho ou mostarda
A15: MD-014 | B15: 4 | C15: Pratos Principais | D15: Carnes | E15: Carnes Bovinas | F15: Lagarto ao molho madeira ou ervas | G15: Personalização | H15: Item avulso | I15: Adicional real | J15: por pessoa | K15: pessoa | M15: R$ 33,00 | P15: 10,0% | Q15: R$ 33,00 | R15: R$ 36,30 | S15: 1,50 | T15: R$ 54,45 | U15: R$ 60,00 | V15: R$ 50,00 | W15: R$ 50,00 | X15: 27,4% | Y15: ativo | Z15: Pode compor o prato principal do evento. Caso o Strogonoff padrão seja removido, este item assume como prato principal escolhido. | AA15: prato_principal | AB15: NÃO | AC15: NÃO | AD15: SIM | AE15: NÃO | AF15: 1 | AH15: NÃO | AI15: NÃO | AJ15: SIM | AK15: somar_quando_selecionado | AL15: Somar ao total quando selecionado. Pode substituir o Strogonoff padrão, sem desconto pela remoção do padrão. | AM15: 50 | AN15: 33 | AO15: R$ 50,00 | AP15: =IF($AA15="prato_principal","SIM","NÃO") -> SIM | AQ15: SIM | AR15: Lagarto ao molho madeira ou ervas
A16: MD-015 | B16: 4 | C16: Pratos Principais | D16: Carnes | E16: Carnes Bovinas | F16: Maminha ao molho barbecue ou madeira | G16: Personalização | H16: Item avulso | I16: Adicional real | J16: por pessoa | K16: pessoa | M16: R$ 33,00 | P16: 10,0% | Q16: R$ 33,00 | R16: R$ 36,30 | S16: 1,50 | T16: R$ 54,45 | U16: R$ 60,00 | V16: R$ 55,00 | W16: R$ 55,00 | X16: 34,0% | Y16: ativo | Z16: Pode compor o prato principal do evento. Caso o Strogonoff padrão seja removido, este item assume como prato principal escolhido. | AA16: prato_principal | AB16: NÃO | AC16: NÃO | AD16: SIM | AE16: NÃO | AF16: 1 | AH16: NÃO | AI16: NÃO | AJ16: SIM | AK16: somar_quando_selecionado | AL16: Somar ao total quando selecionado. Pode substituir o Strogonoff padrão, sem desconto pela remoção do padrão. | AM16: 55 | AN16: 33 | AO16: R$ 55,00 | AP16: =IF($AA16="prato_principal","SIM","NÃO") -> SIM | AQ16: SIM | AR16: Maminha ao molho barbecue ou madeira
A17: MD-016 | B17: 5 | C17: Pratos Principais | D17: Suino | E17: Carnes Suínas | F17: Lombo suíno ao molho agridoce ou abacaxi | G17: Personalização | H17: Item avulso | I17: Adicional real | J17: por pessoa | K17: pessoa | M17: R$ 25,00 | P17: 10,0% | Q17: R$ 25,00 | R17: R$ 27,50 | S17: 1,30 | T17: R$ 35,75 | U17: R$ 40,00 | V17: R$ 35,00 | W17: R$ 35,00 | X17: 21,4% | Y17: ativo | Z17: Pode compor o prato principal do evento. Caso o Strogonoff padrão seja removido, este item assume como prato principal escolhido. | AA17: prato_principal | AB17: NÃO | AC17: NÃO | AD17: SIM | AE17: NÃO | AF17: 1 | AH17: NÃO | AI17: NÃO | AJ17: SIM | AK17: somar_quando_selecionado | AL17: Somar ao total quando selecionado. Pode substituir o Strogonoff padrão, sem desconto pela remoção do padrão. | AM17: 35 | AN17: 25 | AO17: R$ 35,00 | AP17: =IF($AA17="prato_principal","SIM","NÃO") -> SIM | AQ17: SIM | AR17: Lombo suíno ao molho agridoce ou abacaxi
A18: MD-017 | B18: 5 | C18: Pratos Principais | D18: Suino | E18: Carnes Suínas | F18: Pernil ao molho barbecue | G18: Personalização | H18: Item avulso | I18: Adicional real | J18: por pessoa | K18: pessoa | M18: R$ 25,00 | P18: 10,0% | Q18: R$ 25,00 | R18: R$ 27,50 | S18: 1,30 | T18: R$ 35,75 | U18: R$ 40,00 | V18: R$ 35,00 | W18: R$ 35,00 | X18: 21,4% | Y18: ativo | Z18: Pode compor o prato principal do evento. Caso o Strogonoff padrão seja removido, este item assume como prato principal escolhido. | AA18: prato_principal | AB18: NÃO | AC18: NÃO | AD18: SIM | AE18: NÃO | AF18: 1 | AH18: NÃO | AI18: NÃO | AJ18: SIM | AK18: somar_quando_selecionado | AL18: Somar ao total quando selecionado. Pode substituir o Strogonoff padrão, sem desconto pela remoção do padrão. | AM18: 35 | AN18: 25 | AO18: R$ 35,00 | AP18: =IF($AA18="prato_principal","SIM","NÃO") -> SIM | AQ18: SIM | AR18: Pernil ao molho barbecue
A19: MD-018 | B19: 6 | C19: Pratos Principais | D19: Frango | E19: Carnes Frango | F19: Filé de frango ao molho branco, ervas, queijo, mostarda ou madeira, molho de laranja ou limão siciliano | G19: Personalização | H19: Item avulso | I19: Adicional real | J19: por pessoa | K19: pessoa | M19: R$ 25,00 | P19: 10,0% | Q19: R$ 25,00 | R19: R$ 27,50 | S19: 1,30 | T19: R$ 35,75 | U19: R$ 40,00 | V19: R$ 33,00 | W19: R$ 33,00 | X19: 16,7% | Y19: ativo | Z19: Pode compor o prato principal do evento. Caso o Strogonoff padrão seja removido, este item assume como prato principal escolhido. | AA19: prato_principal | AB19: NÃO | AC19: NÃO | AD19: SIM | AE19: NÃO | AF19: 1 | AH19: NÃO | AI19: NÃO | AJ19: SIM | AK19: somar_quando_selecionado | AL19: Somar ao total quando selecionado. Pode substituir o Strogonoff padrão, sem desconto pela remoção do padrão. | AM19: 33 | AN19: 25 | AO19: R$ 33,00 | AP19: =IF($AA19="prato_principal","SIM","NÃO") -> SIM | AQ19: SIM | AR19: Filé de frango ao molho branco, ervas, queijo, mostarda ou madeira, molho de laranja ou limão siciliano
A20: MD-019 | B20: 6 | C20: Pratos Principais | D20: Frango | E20: Carnes Frango | F20: Filé de coxa e sobrecoxa assada | G20: Personalização | H20: Item avulso | I20: Adicional real | J20: por pessoa | K20: pessoa | M20: R$ 20,00 | P20: 10,0% | Q20: R$ 20,00 | R20: R$ 22,00 | S20: 1,30 | T20: R$ 28,60 | U20: R$ 30,00 | V20: R$ 30,00 | W20: R$ 30,00 | X20: 26,7% | Y20: ativo | Z20: Pode compor o prato principal do evento. Caso o Strogonoff padrão seja removido, este item assume como prato principal escolhido. | AA20: prato_principal | AB20: NÃO | AC20: NÃO | AD20: SIM | AE20: NÃO | AF20: 1 | AH20: NÃO | AI20: NÃO | AJ20: SIM | AK20: somar_quando_selecionado | AL20: Somar ao total quando selecionado. Pode substituir o Strogonoff padrão, sem desconto pela remoção do padrão. | AM20: 30 | AN20: 20 | AO20: R$ 30,00 | AP20: =IF($AA20="prato_principal","SIM","NÃO") -> SIM | AQ20: SIM | AR20: Filé de coxa e sobrecoxa assada
A21: MD-020 | B21: 6 | C21: Pratos Principais | D21: Frango | E21: Carnes Frango | F21: Strogonoff de Frango, Batata Palha | G21: Essencial | H21: Item avulso | I21: Adicional real | J21: por pessoa | K21: pessoa | M21: R$ 20,00 | P21: 10,0% | Q21: R$ 20,00 | R21: R$ 22,00 | S21: 1,30 | T21: R$ 28,60 | U21: R$ 30,00 | V21: R$ 30,00 | W21: R$ 30,00 | X21: 26,7% | Y21: ativo | Z21: Strogonoff é uma opção comum de prato principal. Não vem selecionado no simulador; deve ser escolhido como qualquer outro prato principal. | AA21: prato_principal | AB21: NÃO | AC21: NÃO | AD21: SIM | AE21: NÃO | AF21: 1 | AH21: NÃO | AI21: NÃO | AJ21: SIM | AK21: somar_quando_selecionado | AL21: Prato principal comum. O investimento final só é exibido quando houver ao menos 1 item do grupo prato_principal selecionado. | AM21: 30 | AN21: 20 | AO21: R$ 30,00 | AP21: =IF($AA21="prato_principal","SIM","NÃO") -> SIM | AQ21: SIM | AR21: Strogonoff de Frango, Batata Palha
A22: MD-021 | B22: 7 | C22: Pratos Principais | D22: Peixe | E22: Peixe | F22: Salmão ao molho de maracujá ou alcaparras | G22: Personalização | H22: Item avulso | I22: Adicional real | J22: por pessoa | K22: pessoa | M22: R$ 45,00 | P22: 10,0% | Q22: R$ 45,00 | R22: R$ 49,50 | S22: 1,50 | T22: R$ 74,25 | U22: R$ 80,00 | V22: 80 | W22: R$ 80,00 | X22: 38,1% | Y22: ativo | Z22: Pode compor o prato principal do evento. Caso o Strogonoff padrão seja removido, este item assume como prato principal escolhido. | AA22: prato_principal | AB22: NÃO | AC22: NÃO | AD22: SIM | AE22: NÃO | AF22: 1 | AH22: NÃO | AI22: NÃO | AJ22: SIM | AK22: somar_quando_selecionado | AL22: Somar ao total quando selecionado. Pode substituir o Strogonoff padrão, sem desconto pela remoção do padrão. | AM22: 80 | AN22: 45 | AO22: R$ 80,00 | AP22: =IF($AA22="prato_principal","SIM","NÃO") -> SIM | AQ22: SIM | AR22: Salmão ao molho de maracujá ou alcaparras
A23: MD-022 | B23: 7 | C23: Pratos Principais | D23: Peixe | E23: Peixe | F23: Tilápia ao molho de alcaparras ou pimentão e cebola | G23: Personalização | H23: Item avulso | I23: Adicional real | J23: por pessoa | K23: pessoa | M23: R$ 20,00 | P23: 10,0% | Q23: R$ 20,00 | R23: R$ 22,00 | S23: 1,50 | T23: R$ 33,00 | U23: R$ 40,00 | V23: 40 | W23: R$ 40,00 | X23: 45,0% | Y23: ativo | Z23: Pode compor o prato principal do evento. Caso o Strogonoff padrão seja removido, este item assume como prato principal escolhido. | AA23: prato_principal | AB23: NÃO | AC23: NÃO | AD23: SIM | AE23: NÃO | AF23: 1 | AH23: NÃO | AI23: NÃO | AJ23: SIM | AK23: somar_quando_selecionado | AL23: Somar ao total quando selecionado. Pode substituir o Strogonoff padrão, sem desconto pela remoção do padrão. | AM23: 40 | AN23: 20 | AO23: R$ 40,00 | AP23: =IF($AA23="prato_principal","SIM","NÃO") -> SIM | AQ23: SIM | AR23: Tilápia ao molho de alcaparras ou pimentão e cebola
A24: MD-023 | B24: 7 | C24: Pratos Principais | D24: Peixe | E24: Peixe | F24: Ceviche de tilápia | G24: Personalização | H24: Item avulso | I24: Adicional real | J24: por pessoa | K24: pessoa | M24: R$ 20,00 | P24: 10,0% | Q24: R$ 20,00 | R24: R$ 22,00 | S24: 1,50 | T24: R$ 33,00 | U24: R$ 40,00 | V24: 40 | W24: R$ 40,00 | X24: 45,0% | Y24: ativo | Z24: Pode compor o prato principal do evento. Caso o Strogonoff padrão seja removido, este item assume como prato principal escolhido. | AA24: prato_principal | AB24: NÃO | AC24: NÃO | AD24: SIM | AE24: NÃO | AF24: 1 | AH24: NÃO | AI24: NÃO | AJ24: SIM | AK24: somar_quando_selecionado | AL24: Somar ao total quando selecionado. Pode substituir o Strogonoff padrão, sem desconto pela remoção do padrão. | AM24: 40 | AN24: 20 | AO24: R$ 40,00 | AP24: =IF($AA24="prato_principal","SIM","NÃO") -> SIM | AQ24: SIM | AR24: Ceviche de tilápia
A25: MD-024 | B25: 7 | C25: Pratos Principais | D25: Peixe | E25: Peixe | F25: Bobó de camarão | G25: Personalização | H25: Item avulso | I25: Adicional real | J25: por pessoa | K25: pessoa | M25: R$ 32,00 | P25: 10,0% | Q25: R$ 32,00 | R25: R$ 35,20 | S25: 1,50 | T25: R$ 52,80 | U25: R$ 60,00 | V25: 60 | W25: R$ 60,00 | X25: 41,3% | Y25: ativo | Z25: Pode compor o prato principal do evento. Caso o Strogonoff padrão seja removido, este item assume como prato principal escolhido. | AA25: prato_principal | AB25: NÃO | AC25: NÃO | AD25: SIM | AE25: NÃO | AF25: 1 | AH25: NÃO | AI25: NÃO | AJ25: SIM | AK25: somar_quando_selecionado | AL25: Somar ao total quando selecionado. Pode substituir o Strogonoff padrão, sem desconto pela remoção do padrão. | AM25: 60 | AN25: 32 | AO25: R$ 60,00 | AP25: =IF($AA25="prato_principal","SIM","NÃO") -> SIM | AQ25: SIM | AR25: Bobó de camarão
A26: MD-025 | B26: 7 | C26: Pratos Principais | D26: Peixe | E26: Peixe | F26: Saint Peter gratinado | G26: Personalização | H26: Item avulso | I26: Adicional real | J26: por pessoa | K26: pessoa | M26: R$ 30,00 | P26: 10,0% | Q26: R$ 30,00 | R26: R$ 33,00 | S26: 1,50 | T26: R$ 49,50 | U26: R$ 50,00 | V26: 50 | W26: R$ 50,00 | X26: 34,0% | Y26: ativo | Z26: Pode compor o prato principal do evento. Caso o Strogonoff padrão seja removido, este item assume como prato principal escolhido. | AA26: prato_principal | AB26: NÃO | AC26: NÃO | AD26: SIM | AE26: NÃO | AF26: 1 | AH26: NÃO | AI26: NÃO | AJ26: SIM | AK26: somar_quando_selecionado | AL26: Somar ao total quando selecionado. Pode substituir o Strogonoff padrão, sem desconto pela remoção do padrão. | AM26: 50 | AN26: 30 | AO26: R$ 50,00 | AP26: =IF($AA26="prato_principal","SIM","NÃO") -> SIM | AQ26: SIM | AR26: Saint Peter gratinado
A27: MD-026 | B27: 8 | C27: Pratos Principais | D27: Cozinha Mineira | E27: À La Mineira Celebração | F27: Bisteca, Arroz carreteiro, Feijão tropeiro, Couve refogada, Torresmo, Polenta, Farofa de banana | G27: Celebração | H27: Composição | I27: Adicional real | J27: por pessoa | K27: pessoa | M27: R$ 30,00 | P27: 10,0% | Q27: R$ 30,00 | R27: R$ 33,00 | S27: 1,20 | T27: R$ 39,60 | U27: R$ 40,00 | V27: R$ 45,00 | W27: R$ 45,00 | X27: 26,7% | Y27: ativo | AA27: personalizacao | AB27: NÃO | AC27: NÃO | AD27: SIM | AE27: NÃO | AH27: NÃO | AI27: NÃO | AJ27: SIM | AK27: somar_quando_selecionado | AL27: Somar ao total quando selecionado. | AM27: 45 | AN27: 30 | AO27: R$ 45,00 | AP27: SIM | AQ27: SIM | AR27: Bisteca, Arroz carreteiro, Feijão tropeiro, Couve refogada, Torresmo, Polenta, Farofa de banana
A28: MD-027 | B28: 8 | C28: Pratos Principais | D28: Cozinha Mineira | E28: À La Mineira Essencial | F28: Bisteca, Arroz carreteiro, Feijão tropeiro, Couve refogada, Torresmo | G28: Essencial | H28: Composição | I28: Adicional real | J28: por pessoa | K28: pessoa | M28: R$ 30,00 | P28: 10,0% | Q28: R$ 30,00 | R28: R$ 33,00 | S28: 1,20 | T28: R$ 39,60 | U28: R$ 40,00 | V28: R$ 40,00 | W28: R$ 40,00 | X28: 17,5% | Y28: ativo | AA28: personalizacao | AB28: NÃO | AC28: NÃO | AD28: SIM | AE28: NÃO | AH28: NÃO | AI28: NÃO | AJ28: SIM | AK28: somar_quando_selecionado | AL28: Somar ao total quando selecionado. | AM28: 40 | AN28: 30 | AO28: R$ 40,00 | AP28: SIM | AQ28: SIM | AR28: Bisteca, Arroz carreteiro, Feijão tropeiro, Couve refogada, Torresmo
A29: MD-028 | B29: 8 | C29: Pratos Principais | D29: Cozinha Mineira | E29: À La Mineira Premium | F29: Galinhada, Bisteca, Tutu de feijão, Arroz carreteiro, Feijão tropeiro, Couve refogada, Torresmo, Polenta cremosa, Farofa de banana | G29: Premium | H29: Composição | I29: Adicional real | J29: por pessoa | K29: pessoa | M29: R$ 33,00 | P29: 10,0% | Q29: R$ 33,00 | R29: R$ 36,30 | S29: 1,50 | T29: R$ 54,45 | U29: R$ 60,00 | V29: 60 | W29: R$ 60,00 | X29: 39,5% | Y29: ativo | AA29: personalizacao | AB29: NÃO | AC29: NÃO | AD29: SIM | AE29: NÃO | AH29: NÃO | AI29: NÃO | AJ29: SIM | AK29: somar_quando_selecionado | AL29: Somar ao total quando selecionado. | AM29: 60 | AN29: 33 | AO29: R$ 60,00 | AP29: SIM | AQ29: SIM | AR29: Galinhada, Bisteca, Tutu de feijão, Arroz carreteiro, Feijão tropeiro, Couve refogada, Torresmo, Polenta cremosa, Farofa de banana
A30: MD-029 | B30: 9 | C30: Na Brasa Margô | D30: Brasa Clássica | E30: À La Brasa Clássica | F30: Contra filé, linguiça e frango | G30: Essencial | H30: Composição | I30: Adicional real | J30: por pessoa | K30: pessoa | M30: R$ 21,00 | P30: 12,0% | Q30: R$ 21,00 | R30: R$ 23,52 | S30: 2,70 | T30: R$ 63,50 | U30: R$ 70,00 | V30: R$ 65,00 | W30: R$ 65,00 | X30: 63,8% | Y30: ativo | AA30: prato_principal | AB30: NÃO | AC30: NÃO | AD30: SIM | AE30: NÃO | AF30: 1 | AG30: 1 | AH30: NÃO | AI30: NÃO | AJ30: SIM | AK30: somar_quando_selecionado | AL30: Pode ser escolhido como prato principal. Somar quando selecionado. | AM30: 65 | AN30: 21 | AO30: R$ 65,00 | AP30: =IF($AA30="prato_principal","SIM","NÃO") -> SIM | AQ30: SIM | AR30: Contra filé, linguiça e frango
A31: MD-030 | B31: 10 | C31: Na Brasa Margô | D31: Brasa Nobre | E31: À La Brasa Nobre | F31: Contra filé, linguiça, filé de coxa e sobrecoxa, maminha na manteiga e cupim | G31: Celebração | H31: Composição | I31: Adicional real | J31: por pessoa | K31: pessoa | M31: R$ 24,00 | P31: 12,0% | Q31: R$ 24,00 | R31: R$ 26,88 | S31: 2,70 | T31: R$ 72,58 | U31: R$ 80,00 | V31: R$ 80,00 | W31: R$ 80,00 | X31: 66,4% | Y31: ativo | AA31: prato_principal | AB31: NÃO | AC31: NÃO | AD31: SIM | AE31: NÃO | AF31: 1 | AG31: 1 | AH31: NÃO | AI31: NÃO | AJ31: SIM | AK31: somar_quando_selecionado | AL31: Pode ser escolhido como prato principal. Somar quando selecionado. | AM31: 80 | AN31: 24 | AO31: R$ 80,00 | AP31: =IF($AA31="prato_principal","SIM","NÃO") -> SIM | AQ31: SIM | AR31: Contra filé, linguiça, filé de coxa e sobrecoxa, maminha na manteiga e cupim
A32: MD-031 | B32: 11 | C32: Na Brasa Margô | D32: Brasa Premium | E32: À La Brasa Premium | F32: Costela bovina, Contra filé, linguiça, filé de coxa e sobrecoxa, maminha na manteiga, cupim, picanha e panceta | G32: Premium | H32: Composição | I32: Adicional real | J32: por pessoa | K32: pessoa | M32: R$ 50,00 | P32: 12,0% | Q32: R$ 50,00 | R32: R$ 56,00 | S32: 2,70 | T32: R$ 151,20 | U32: R$ 160,00 | V32: R$ 160,00 | W32: R$ 160,00 | X32: 65,0% | Y32: ativo | AA32: prato_principal | AB32: NÃO | AC32: NÃO | AD32: SIM | AE32: NÃO | AF32: 1 | AG32: 1 | AH32: NÃO | AI32: NÃO | AJ32: SIM | AK32: somar_quando_selecionado | AL32: Pode ser escolhido como prato principal. Somar quando selecionado. | AM32: 160 | AN32: 50 | AO32: R$ 160,00 | AP32: =IF($AA32="prato_principal","SIM","NÃO") -> SIM | AQ32: SIM | AR32: Costela bovina, Contra filé, linguiça, filé de coxa e sobrecoxa, maminha na manteiga, cupim, picanha e panceta
A33: MD-032 | B33: 12 | C33: Na Brasa Margô | D33: Complementos na Brasa | E33: Complemento da Brasa Celebração | F33: Tulipa, Kafta, Pão de queijo, Pão de alho, Coração | G33: Personalização | H33: Complemento | I33: Adicional real | J33: por pessoa | K33: pessoa | M33: R$ 4,30 | P33: 12,0% | Q33: R$ 4,30 | R33: R$ 4,82 | S33: 3,00 | T33: R$ 14,45 | U33: R$ 20,00 | V33: R$ 15,00 | W33: R$ 15,00 | X33: 67,9% | Y33: ativo | AA33: brasa_complemento | AB33: NÃO | AC33: NÃO | AD33: SIM | AE33: NÃO | AH33: NÃO | AI33: NÃO | AJ33: SIM | AK33: somar_quando_selecionado | AL33: Complemento da Brasa. Somar ao total quando selecionado. | AM33: 15 | AN33: 4.3 | AO33: R$ 15,00 | AP33: =IF($AA33="prato_principal","SIM","NÃO") -> NÃO | AQ33: SIM | AR33: Tulipa, Kafta, Pão de queijo, Pão de alho, Coração
A34: MD-033 | B34: 12 | C34: Na Brasa Margô | D34: Complementos na Brasa | E34: Complemento da Brasa Essencial | F34: Kafta, Pão de alho, Coração | G34: Personalização | H34: Complemento | I34: Adicional real | J34: por pessoa | K34: pessoa | M34: R$ 3,80 | P34: 12,0% | Q34: R$ 3,80 | R34: R$ 4,26 | S34: 3,00 | T34: R$ 12,77 | U34: R$ 20,00 | V34: R$ 12,00 | W34: R$ 12,00 | X34: 64,5% | Y34: ativo | AA34: brasa_complemento | AB34: NÃO | AC34: NÃO | AD34: SIM | AE34: NÃO | AH34: NÃO | AI34: NÃO | AJ34: SIM | AK34: somar_quando_selecionado | AL34: Complemento da Brasa. Somar ao total quando selecionado. | AM34: 12 | AN34: 3.8 | AO34: R$ 12,00 | AP34: =IF($AA34="prato_principal","SIM","NÃO") -> NÃO | AQ34: SIM | AR34: Kafta, Pão de alho, Coração
A35: MD-034 | B35: 12 | C35: Na Brasa Margô | D35: Complementos na Brasa | E35: Complemento da Brasa Premium | F35: Tulipa, Queijo coalho, Kafta, Pão de queijo, Pão de alho, Coração | G35: Premium | H35: Complemento | I35: Adicional real | J35: por pessoa | K35: pessoa | M35: R$ 5,00 | P35: 12,0% | Q35: R$ 5,00 | R35: R$ 5,60 | S35: 3,00 | T35: R$ 16,80 | U35: R$ 20,00 | V35: R$ 17,00 | W35: R$ 17,00 | X35: 67,1% | Y35: ativo | AA35: brasa_complemento | AB35: NÃO | AC35: NÃO | AD35: SIM | AE35: NÃO | AH35: NÃO | AI35: NÃO | AJ35: SIM | AK35: somar_quando_selecionado | AL35: Complemento da Brasa. Somar ao total quando selecionado. | AM35: 17 | AN35: 5 | AO35: R$ 17,00 | AP35: =IF($AA35="prato_principal","SIM","NÃO") -> NÃO | AQ35: SIM | AR35: Tulipa, Queijo coalho, Kafta, Pão de queijo, Pão de alho, Coração
A36: MD-035 | B36: 13 | C36: Na Brasa Margô | D36: Brasa Especial | E36: À La Brasa | F36: Costelinha suína barbecue | G36: Personalização | H36: Complemento | I36: Adicional real | J36: por pessoa | K36: pessoa | M36: R$ 5,00 | P36: 12,0% | Q36: R$ 5,00 | R36: R$ 5,60 | S36: 3,00 | T36: R$ 16,80 | U36: R$ 20,00 | V36: R$ 17,00 | W36: R$ 17,00 | X36: 67,1% | Y36: ativo | AA36: brasa_complemento | AB36: NÃO | AC36: NÃO | AD36: SIM | AE36: NÃO | AH36: NÃO | AI36: NÃO | AJ36: SIM | AK36: somar_quando_selecionado | AL36: Complemento da Brasa. Somar ao total quando selecionado. | AM36: 17 | AN36: 5 | AO36: R$ 17,00 | AP36: =IF($AA36="prato_principal","SIM","NÃO") -> NÃO | AQ36: SIM | AR36: Costelinha suína barbecue
A37: MD-036 | B37: 14 | C37: Massas & Saladas | D37: Festival Clássico | E37: Festival Clássico | F37: Nhoque ao sugo, Massa ao molho de tomate fresco, Fettuccine ao molho branco ou ervas, Lasanha de frango | G37: Essencial | H37: Composição | I37: Adicional real | J37: por pessoa | K37: pessoa | M37: R$ 30,00 | P37: 10,0% | Q37: R$ 30,00 | R37: R$ 33,00 | S37: 2,00 | T37: R$ 66,00 | U37: R$ 70,00 | V37: R$ 70,00 | W37: R$ 70,00 | X37: 52,9% | Y37: ativo | AA37: massas_estacoes | AB37: NÃO | AC37: NÃO | AD37: SIM | AE37: NÃO | AG37: 1 | AH37: NÃO | AI37: NÃO | AJ37: SIM | AK37: somar_quando_selecionado | AL37: Selecionar no máximo 1 festival de massas. Somar ao total quando selecionado. | AM37: 70 | AN37: 30 | AO37: R$ 70,00 | AP37: SIM | AQ37: SIM | AR37: Nhoque ao sugo, Massa ao molho de tomate fresco, Fettuccine ao molho branco ou ervas, Lasanha de frango
A38: MD-037 | B38: 15 | C38: Massas & Saladas | D38: Festival Cremoso | E38: Festival Cremoso | F38: Nhoque ao molho branco, Massa ao molho quatro queijos, Lasanha quatro queijos, Rondelli de queijo | G38: Celebração | H38: Composição | I38: Adicional real | J38: por pessoa | K38: pessoa | M38: R$ 30,00 | P38: 10,0% | Q38: R$ 30,00 | R38: R$ 33,00 | S38: 2,50 | T38: R$ 82,50 | U38: R$ 90,00 | V38: R$ 80,00 | W38: R$ 80,00 | X38: 58,8% | Y38: ativo | AA38: massas_estacoes | AB38: NÃO | AC38: NÃO | AD38: SIM | AE38: NÃO | AG38: 1 | AH38: NÃO | AI38: NÃO | AJ38: SIM | AK38: somar_quando_selecionado | AL38: Selecionar no máximo 1 festival de massas. Somar ao total quando selecionado. | AM38: 80 | AN38: 30 | AO38: R$ 80,00 | AP38: SIM | AQ38: SIM | AR38: Nhoque ao molho branco, Massa ao molho quatro queijos, Lasanha quatro queijos, Rondelli de queijo
